2023-05-14 13:49:46 - Browser 1 - INFO - 正在啟動裝置 - create_webdriver - "C:\Users\User\PycharmProjects\Socializing\core\webdriver.py:32"

2023-05-14 13:49:47 - Browser 1 - INFO - Starting Chrome - <module> - "<string>:4"

2023-05-14 13:50:14 - Browser 1 - INFO - 正在啟動裝置 - create_webdriver - "C:\Users\User\PycharmProjects\Socializing\core\webdriver.py:32"

2023-05-14 13:50:16 - Browser 1 - INFO - Starting Chrome - <module> - "<string>:4"

2023-05-14 13:50:36 - Browser 1 - INFO - 正在啟動裝置 - create_webdriver - "C:\Users\User\PycharmProjects\Socializing\core\webdriver.py:32"

2023-05-14 13:52:41 - Browser 1 - INFO - 正在啟動裝置 - create_webdriver - "C:\Users\User\PycharmProjects\Socializing\core\webdriver.py:32"

2023-05-14 13:52:48 - Browser 1 - INFO - Starting Chrome - <module> - "<string>:4"

2023-05-14 16:41:24 - Browser 1 - INFO - 正在啟動裝置 - create_webdriver - "C:\Users\User\PycharmProjects\Socializing\core\webdriver.py:32"

2023-05-14 16:41:43 - Browser 1 - INFO - 正在啟動裝置 - create_webdriver - "C:\Users\User\PycharmProjects\Socializing\core\webdriver.py:32"

2023-05-14 16:41:59 - Browser 1 - ERROR - Message: disconnected: not connected to DevTools
  (failed to check if window was closed: disconnected: not connected to DevTools)
  (Session info: chrome=113.0.5672.93)
Stacktrace:
Backtrace:
	GetHandleVerifier [0x00B18893+48451]
	(No symbol) [0x00AAB8A1]
	(No symbol) [0x009B5058]
	(No symbol) [0x009A7BB6]
	(No symbol) [0x009A78D9]
	(No symbol) [0x009B6460]
	(No symbol) [0x00A0C038]
	(No symbol) [0x009FA0B6]
	(No symbol) [0x009D7E08]
	(No symbol) [0x009D8F2D]
	GetHandleVerifier [0x00D78E3A+2540266]
	GetHandleVerifier [0x00DB8959+2801161]
	GetHandleVerifier [0x00DB295C+2776588]
	GetHandleVerifier [0x00BA2280+612144]
	(No symbol) [0x00AB4F6C]
	(No symbol) [0x00AB11D8]
	(No symbol) [0x00AB12BB]
	(No symbol) [0x00AA4857]
	BaseThreadInitThunk [0x754E00C9+25]
	RtlGetAppContainerNamedObjectPath [0x771E7B4E+286]
	RtlGetAppContainerNamedObjectPath [0x771E7B1E+238]
 - run_script - "C:\Users\User\PycharmProjects\Socializing\core\webdriver.py:104"
Traceback (most recent call last):
  File "C:\Users\User\PycharmProjects\Socializing\core\webdriver.py", line 102, in run_script
    exec(script)
  File "<string>", line 11, in <module>
  File "C:\Users\User\PycharmProjects\Socializing\venv\lib\site-packages\selenium\webdriver\support\wait.py", line 86, in until
    value = method(self._driver)
  File "C:\Users\User\PycharmProjects\Socializing\venv\lib\site-packages\selenium\webdriver\support\expected_conditions.py", line 69, in _predicate
    return driver.find_element(*locator)
  File "C:\Users\User\PycharmProjects\Socializing\venv\lib\site-packages\selenium\webdriver\remote\webdriver.py", line 831, in find_element
    return self.execute(Command.FIND_ELEMENT, {"using": by, "value": value})["value"]
  File "C:\Users\User\PycharmProjects\Socializing\venv\lib\site-packages\selenium\webdriver\remote\webdriver.py", line 440, in execute
    self.error_handler.check_response(response)
  File "C:\Users\User\PycharmProjects\Socializing\venv\lib\site-packages\selenium\webdriver\remote\errorhandler.py", line 245, in check_response
    raise exception_class(message, screen, stacktrace)
selenium.common.exceptions.WebDriverException: Message: disconnected: not connected to DevTools
  (failed to check if window was closed: disconnected: not connected to DevTools)
  (Session info: chrome=113.0.5672.93)
Stacktrace:
Backtrace:
	GetHandleVerifier [0x00B18893+48451]
	(No symbol) [0x00AAB8A1]
	(No symbol) [0x009B5058]
	(No symbol) [0x009A7BB6]
	(No symbol) [0x009A78D9]
	(No symbol) [0x009B6460]
	(No symbol) [0x00A0C038]
	(No symbol) [0x009FA0B6]
	(No symbol) [0x009D7E08]
	(No symbol) [0x009D8F2D]
	GetHandleVerifier [0x00D78E3A+2540266]
	GetHandleVerifier [0x00DB8959+2801161]
	GetHandleVerifier [0x00DB295C+2776588]
	GetHandleVerifier [0x00BA2280+612144]
	(No symbol) [0x00AB4F6C]
	(No symbol) [0x00AB11D8]
	(No symbol) [0x00AB12BB]
	(No symbol) [0x00AA4857]
	BaseThreadInitThunk [0x754E00C9+25]
	RtlGetAppContainerNamedObjectPath [0x771E7B4E+286]
	RtlGetAppContainerNamedObjectPath [0x771E7B1E+238]


2023-05-14 16:42:44 - Browser 1 - INFO - 正在啟動裝置 - create_webdriver - "C:\Users\User\PycharmProjects\Socializing\core\webdriver.py:32"

2023-05-14 16:43:03 - Browser 1 - ERROR - Message: 
Stacktrace:
Backtrace:
	GetHandleVerifier [0x00FA8893+48451]
	(No symbol) [0x00F3B8A1]
	(No symbol) [0x00E45058]
	(No symbol) [0x00E70467]
	(No symbol) [0x00E7069B]
	(No symbol) [0x00E9DD92]
	(No symbol) [0x00E8A304]
	(No symbol) [0x00E9C482]
	(No symbol) [0x00E8A0B6]
	(No symbol) [0x00E67E08]
	(No symbol) [0x00E68F2D]
	GetHandleVerifier [0x01208E3A+2540266]
	GetHandleVerifier [0x01248959+2801161]
	GetHandleVerifier [0x0124295C+2776588]
	GetHandleVerifier [0x01032280+612144]
	(No symbol) [0x00F44F6C]
	(No symbol) [0x00F411D8]
	(No symbol) [0x00F412BB]
	(No symbol) [0x00F34857]
	BaseThreadInitThunk [0x754E00C9+25]
	RtlGetAppContainerNamedObjectPath [0x771E7B4E+286]
	RtlGetAppContainerNamedObjectPath [0x771E7B1E+238]
 - run_script - "C:\Users\User\PycharmProjects\Socializing\core\webdriver.py:105"
Traceback (most recent call last):
  File "C:\Users\User\PycharmProjects\Socializing\core\webdriver.py", line 103, in run_script
    exec(script)
  File "<string>", line 11, in <module>
  File "C:\Users\User\PycharmProjects\Socializing\venv\lib\site-packages\selenium\webdriver\support\wait.py", line 95, in until
    raise TimeoutException(message, screen, stacktrace)
selenium.common.exceptions.TimeoutException: Message: 
Stacktrace:
Backtrace:
	GetHandleVerifier [0x00FA8893+48451]
	(No symbol) [0x00F3B8A1]
	(No symbol) [0x00E45058]
	(No symbol) [0x00E70467]
	(No symbol) [0x00E7069B]
	(No symbol) [0x00E9DD92]
	(No symbol) [0x00E8A304]
	(No symbol) [0x00E9C482]
	(No symbol) [0x00E8A0B6]
	(No symbol) [0x00E67E08]
	(No symbol) [0x00E68F2D]
	GetHandleVerifier [0x01208E3A+2540266]
	GetHandleVerifier [0x01248959+2801161]
	GetHandleVerifier [0x0124295C+2776588]
	GetHandleVerifier [0x01032280+612144]
	(No symbol) [0x00F44F6C]
	(No symbol) [0x00F411D8]
	(No symbol) [0x00F412BB]
	(No symbol) [0x00F34857]
	BaseThreadInitThunk [0x754E00C9+25]
	RtlGetAppContainerNamedObjectPath [0x771E7B4E+286]
	RtlGetAppContainerNamedObjectPath [0x771E7B1E+238]


2023-05-14 16:48:29 - Browser 1 - INFO - 正在啟動裝置 - create_webdriver - "C:\Users\User\PycharmProjects\Socializing\core\webdriver.py:32"

2023-05-14 17:00:47 - Browser 1 - INFO - 正在啟動裝置 - create_webdriver - "C:\Users\User\PycharmProjects\Socializing\core\webdriver.py:32"

2023-05-14 17:02:16 - Browser 1 - INFO - 正在啟動裝置 - create_webdriver - "C:\Users\User\PycharmProjects\Socializing\core\webdriver.py:34"

2023-05-14 17:03:55 - Browser 1 - INFO - 正在啟動裝置 - create_webdriver - "C:\Users\User\PycharmProjects\Socializing\core\webdriver.py:35"

2023-05-14 17:16:27 - Browser 1 - INFO - 正在啟動裝置 - create_webdriver - "C:\Users\User\PycharmProjects\Socializing\core\webdriver.py:41"

2023-05-14 17:17:25 - Browser 1 - INFO - 正在啟動裝置 - create_webdriver - "C:\Users\User\PycharmProjects\Socializing\core\webdriver.py:41"

2023-05-14 17:18:38 - Browser 1 - ERROR - HTTPConnectionPool(host='localhost', port=8115): Max retries exceeded with url: /session/487c84da70a191ff96dac16913aee964/url (Caused by NewConnectionError('<urllib3.connection.HTTPConnection object at 0x0000016A61D049A0>: Failed to establish a new connection: [WinError 10061] 無法連線，因為目標電腦拒絕連線。')) - run_script - "C:\Users\User\PycharmProjects\Socializing\core\webdriver.py:120"
Traceback (most recent call last):
  File "C:\Users\User\PycharmProjects\Socializing\venv\lib\site-packages\urllib3\connection.py", line 200, in _new_conn
    sock = connection.create_connection(
  File "C:\Users\User\PycharmProjects\Socializing\venv\lib\site-packages\urllib3\util\connection.py", line 85, in create_connection
    raise err
  File "C:\Users\User\PycharmProjects\Socializing\venv\lib\site-packages\urllib3\util\connection.py", line 73, in create_connection
    sock.connect(sa)
ConnectionRefusedError: [WinError 10061] 無法連線，因為目標電腦拒絕連線。

The above exception was the direct cause of the following exception:

Traceback (most recent call last):
  File "C:\Users\User\PycharmProjects\Socializing\venv\lib\site-packages\urllib3\connectionpool.py", line 790, in urlopen
    response = self._make_request(
  File "C:\Users\User\PycharmProjects\Socializing\venv\lib\site-packages\urllib3\connectionpool.py", line 496, in _make_request
    conn.request(
  File "C:\Users\User\PycharmProjects\Socializing\venv\lib\site-packages\urllib3\connection.py", line 388, in request
    self.endheaders()
  File "C:\Users\User\AppData\Local\Programs\Python\Python39\lib\http\client.py", line 1280, in endheaders
    self._send_output(message_body, encode_chunked=encode_chunked)
  File "C:\Users\User\AppData\Local\Programs\Python\Python39\lib\http\client.py", line 1040, in _send_output
    self.send(msg)
  File "C:\Users\User\AppData\Local\Programs\Python\Python39\lib\http\client.py", line 980, in send
    self.connect()
  File "C:\Users\User\PycharmProjects\Socializing\venv\lib\site-packages\urllib3\connection.py", line 236, in connect
    self.sock = self._new_conn()
  File "C:\Users\User\PycharmProjects\Socializing\venv\lib\site-packages\urllib3\connection.py", line 215, in _new_conn
    raise NewConnectionError(
urllib3.exceptions.NewConnectionError: <urllib3.connection.HTTPConnection object at 0x0000016A61D049A0>: Failed to establish a new connection: [WinError 10061] 無法連線，因為目標電腦拒絕連線。

The above exception was the direct cause of the following exception:

Traceback (most recent call last):
  File "C:\Users\User\PycharmProjects\Socializing\core\webdriver.py", line 118, in run_script
    exec(script)
  File "<string>", line 11, in <module>
  File "C:\Users\User\PycharmProjects\Socializing\venv\lib\site-packages\undetected_chromedriver\__init__.py", line 645, in get
    return super().get(url)
  File "C:\Users\User\PycharmProjects\Socializing\venv\lib\site-packages\selenium\webdriver\remote\webdriver.py", line 449, in get
    self.execute(Command.GET, {"url": url})
  File "C:\Users\User\PycharmProjects\Socializing\venv\lib\site-packages\selenium\webdriver\remote\webdriver.py", line 438, in execute
    response = self.command_executor.execute(driver_command, params)
  File "C:\Users\User\PycharmProjects\Socializing\venv\lib\site-packages\selenium\webdriver\remote\remote_connection.py", line 290, in execute
    return self._request(command_info[0], url, body=data)
  File "C:\Users\User\PycharmProjects\Socializing\venv\lib\site-packages\selenium\webdriver\remote\remote_connection.py", line 311, in _request
    response = self._conn.request(method, url, body=body, headers=headers)
  File "C:\Users\User\PycharmProjects\Socializing\venv\lib\site-packages\urllib3\_request_methods.py", line 118, in request
    return self.request_encode_body(
  File "C:\Users\User\PycharmProjects\Socializing\venv\lib\site-packages\urllib3\_request_methods.py", line 217, in request_encode_body
    return self.urlopen(method, url, **extra_kw)
  File "C:\Users\User\PycharmProjects\Socializing\venv\lib\site-packages\urllib3\poolmanager.py", line 433, in urlopen
    response = conn.urlopen(method, u.request_uri, **kw)
  File "C:\Users\User\PycharmProjects\Socializing\venv\lib\site-packages\urllib3\connectionpool.py", line 874, in urlopen
    return self.urlopen(
  File "C:\Users\User\PycharmProjects\Socializing\venv\lib\site-packages\urllib3\connectionpool.py", line 874, in urlopen
    return self.urlopen(
  File "C:\Users\User\PycharmProjects\Socializing\venv\lib\site-packages\urllib3\connectionpool.py", line 874, in urlopen
    return self.urlopen(
  File "C:\Users\User\PycharmProjects\Socializing\venv\lib\site-packages\urllib3\connectionpool.py", line 844, in urlopen
    retries = retries.increment(
  File "C:\Users\User\PycharmProjects\Socializing\venv\lib\site-packages\urllib3\util\retry.py", line 515, in increment
    raise MaxRetryError(_pool, url, reason) from reason  # type: ignore[arg-type]
urllib3.exceptions.MaxRetryError: HTTPConnectionPool(host='localhost', port=8115): Max retries exceeded with url: /session/487c84da70a191ff96dac16913aee964/url (Caused by NewConnectionError('<urllib3.connection.HTTPConnection object at 0x0000016A61D049A0>: Failed to establish a new connection: [WinError 10061] 無法連線，因為目標電腦拒絕連線。'))

2023-05-14 17:19:49 - Browser 1 - INFO - 正在啟動裝置 - create_webdriver - "C:\Users\User\PycharmProjects\Socializing\core\webdriver.py:41"

2023-05-14 17:20:13 - Browser 1 - INFO - 正在啟動裝置 - create_webdriver - "C:\Users\User\PycharmProjects\Socializing\core\webdriver.py:40"

2023-05-14 17:21:04 - Browser 1 - INFO - 正在啟動裝置 - create_webdriver - "C:\Users\User\PycharmProjects\Socializing\core\webdriver.py:41"

2023-05-14 17:22:24 - Browser 1 - INFO - 初始化裝置 - create_webdriver - "C:\Users\User\PycharmProjects\Socializing\core\webdriver.py:41"

2023-05-14 17:22:40 - Browser 1 - INFO - 初始化裝置 - create_webdriver - "C:\Users\User\PycharmProjects\Socializing\core\webdriver.py:41"

2023-05-14 17:22:57 - Browser 1 - INFO - 初始化裝置 - create_webdriver - "C:\Users\User\PycharmProjects\Socializing\core\webdriver.py:41"

2023-05-14 17:23:14 - Browser 1 - INFO - 初始化裝置 - create_webdriver - "C:\Users\User\PycharmProjects\Socializing\core\webdriver.py:41"

2023-05-14 17:23:42 - Browser 1 - INFO - 初始化裝置 - create_webdriver - "C:\Users\User\PycharmProjects\Socializing\core\webdriver.py:41"

2023-05-14 17:23:44 - Browser 1 - INFO - 初始化裝置成功 - run_script - "C:\Users\User\PycharmProjects\Socializing\core\webdriver.py:99"
2023-05-14 17:23:44 - Browser 1 - ERROR - 'return' outside function (<string>, line 29) - run_script - "C:\Users\User\PycharmProjects\Socializing\core\webdriver.py:121"
Traceback (most recent call last):
  File "C:\Users\User\PycharmProjects\Socializing\core\webdriver.py", line 119, in run_script
    exec(script)
  File "<string>", line 29
SyntaxError: 'return' outside function

2023-05-14 17:24:19 - Browser 1 - INFO - 初始化裝置 - create_webdriver - "C:\Users\User\PycharmProjects\Socializing\core\webdriver.py:41"

2023-05-14 17:24:28 - Browser 1 - INFO - 初始化裝置 - create_webdriver - "C:\Users\User\PycharmProjects\Socializing\core\webdriver.py:41"

2023-05-14 17:24:29 - Browser 1 - INFO - 初始化裝置成功 - run_script - "C:\Users\User\PycharmProjects\Socializing\core\webdriver.py:99"

2023-05-14 17:25:11 - Browser 1 - INFO - 初始化裝置 - create_webdriver - "C:\Users\User\PycharmProjects\Socializing\core\webdriver.py:41"

2023-05-14 17:25:13 - Browser 1 - INFO - 初始化裝置成功 - run_script - "C:\Users\User\PycharmProjects\Socializing\core\webdriver.py:99"

2023-05-14 17:25:36 - Browser 1 - INFO - 初始化裝置 - create_webdriver - "C:\Users\User\PycharmProjects\Socializing\core\webdriver.py:41"

2023-05-14 17:25:37 - Browser 1 - INFO - 初始化裝置成功 - run_script - "C:\Users\User\PycharmProjects\Socializing\core\webdriver.py:99"

2023-05-14 17:26:19 - Browser 1 - INFO - 初始化裝置 - create_webdriver - "C:\Users\User\PycharmProjects\Socializing\core\webdriver.py:41"

2023-05-14 17:26:26 - Browser 1 - INFO - 初始化裝置 - create_webdriver - "C:\Users\User\PycharmProjects\Socializing\core\webdriver.py:41"

2023-05-14 17:49:26 - Browser 1 - INFO - 初始化裝置 - create_webdriver - "C:\Users\User\PycharmProjects\Socializing\core\webdriver.py:41"

2023-05-14 17:49:28 - Browser 1 - INFO - 初始化裝置成功 - run_script - "C:\Users\User\PycharmProjects\Socializing\core\webdriver.py:99"

2023-05-14 17:49:31 - Browser 1 - INFO - 檢測到其餘排程，強制結束休息 - <module> - "<string>:26"
2023-05-14 17:49:31 - Browser 1 - INFO - 初始化裝置成功 - run_script - "C:\Users\User\PycharmProjects\Socializing\core\webdriver.py:99"

2023-05-14 18:26:59 - Browser 1 - INFO - 初始化裝置 - create_webdriver - "C:\Users\User\PycharmProjects\Socializing\core\webdriver.py:42"

2023-05-14 18:27:01 - Browser 1 - INFO - 初始化裝置成功 - run_script - "C:\Users\User\PycharmProjects\Socializing\core\webdriver.py:100"

2023-05-14 18:27:44 - Browser 1 - INFO - 初始化裝置 - create_webdriver - "C:\Users\User\PycharmProjects\Socializing\core\webdriver.py:42"

2023-05-14 18:27:45 - Browser 1 - INFO - 初始化裝置成功 - run_script - "C:\Users\User\PycharmProjects\Socializing\core\webdriver.py:100"

2023-05-14 18:28:41 - Browser 1 - INFO - 初始化裝置 - create_webdriver - "C:\Users\User\PycharmProjects\Socializing\core\webdriver.py:42"

2023-05-14 18:28:43 - Browser 1 - INFO - 初始化裝置成功 - run_script - "C:\Users\User\PycharmProjects\Socializing\core\webdriver.py:100"

2023-05-14 18:35:46 - Browser 1 - INFO - 初始化裝置 - create_webdriver - "C:\Users\User\PycharmProjects\Socializing\core\webdriver.py:42"

2023-05-14 18:35:49 - Browser 1 - INFO - 初始化裝置成功 - run_script - "C:\Users\User\PycharmProjects\Socializing\core\webdriver.py:100"

2023-05-14 18:36:39 - Browser 1 - INFO - 初始化裝置 - create_webdriver - "C:\Users\User\PycharmProjects\Socializing\core\webdriver.py:42"

2023-05-14 18:36:44 - Browser 1 - INFO - 初始化裝置成功 - run_script - "C:\Users\User\PycharmProjects\Socializing\core\webdriver.py:100"

2023-05-14 18:38:22 - Browser 1 - INFO - 初始化裝置 - create_webdriver - "C:\Users\User\PycharmProjects\Socializing\core\webdriver.py:42"

2023-05-14 18:38:30 - Browser 1 - INFO - 初始化裝置成功 - run_script - "C:\Users\User\PycharmProjects\Socializing\core\webdriver.py:100"

2023-05-14 22:13:10 - Browser 1 - INFO - 初始化裝置 - create_webdriver - "C:\Users\User\PycharmProjects\Socializing\core\webdriver.py:42"

2023-05-14 22:13:26 - Browser 1 - INFO - 初始化裝置成功 - run_script - "C:\Users\User\PycharmProjects\Socializing\core\webdriver.py:100"

2023-05-14 22:13:31 - Browser 1 - INFO - 已進入直播間 - <module> - "<string>:19"
2023-05-14 22:13:31 - Browser 1 - INFO - 點擊留言框 - <module> - "<string>:20"
2023-05-14 22:13:31 - Browser 1 - ERROR - 'str' object is not callable - run_script - "C:\Users\User\PycharmProjects\Socializing\core\webdriver.py:123"
Traceback (most recent call last):
  File "C:\Users\User\PycharmProjects\Socializing\core\webdriver.py", line 121, in run_script
    exec(script)
  File "<string>", line 21, in <module>
TypeError: 'str' object is not callable

2023-05-14 22:14:51 - Browser 1 - INFO - 初始化裝置 - create_webdriver - "C:\Users\User\PycharmProjects\Socializing\core\webdriver.py:42"

2023-05-14 22:16:02 - Browser 1 - ERROR - Message: unknown error: cannot connect to chrome at 127.0.0.1:11649
from chrome not reachable
Stacktrace:
Backtrace:
	GetHandleVerifier [0x00688893+48451]
	(No symbol) [0x0061B8A1]
	(No symbol) [0x00524F20]
	(No symbol) [0x0051B0E5]
	(No symbol) [0x00545858]
	(No symbol) [0x00540151]
	(No symbol) [0x0053FF31]
	(No symbol) [0x00570798]
	(No symbol) [0x0057047C]
	(No symbol) [0x0056A0B6]
	(No symbol) [0x00547E08]
	(No symbol) [0x00548F2D]
	GetHandleVerifier [0x008E8E3A+2540266]
	GetHandleVerifier [0x00928959+2801161]
	GetHandleVerifier [0x0092295C+2776588]
	GetHandleVerifier [0x00712280+612144]
	(No symbol) [0x00624F6C]
	(No symbol) [0x006211D8]
	(No symbol) [0x006212BB]
	(No symbol) [0x00614857]
	BaseThreadInitThunk [0x754E00C9+25]
	RtlGetAppContainerNamedObjectPath [0x771E7B4E+286]
	RtlGetAppContainerNamedObjectPath [0x771E7B1E+238]
 - create_webdriver - "C:\Users\User\PycharmProjects\Socializing\core\webdriver.py:51"
Traceback (most recent call last):
  File "C:\Users\User\PycharmProjects\Socializing\core\webdriver.py", line 49, in create_webdriver
    return uc.Chrome(**kwargs)
  File "C:\Users\User\PycharmProjects\Socializing\venv\lib\site-packages\undetected_chromedriver\__init__.py", line 441, in __init__
    super(Chrome, self).__init__(
  File "C:\Users\User\PycharmProjects\Socializing\venv\lib\site-packages\selenium\webdriver\chrome\webdriver.py", line 84, in __init__
    super().__init__(
  File "C:\Users\User\PycharmProjects\Socializing\venv\lib\site-packages\selenium\webdriver\chromium\webdriver.py", line 104, in __init__
    super().__init__(
  File "C:\Users\User\PycharmProjects\Socializing\venv\lib\site-packages\selenium\webdriver\remote\webdriver.py", line 286, in __init__
    self.start_session(capabilities, browser_profile)
  File "C:\Users\User\PycharmProjects\Socializing\venv\lib\site-packages\undetected_chromedriver\__init__.py", line 704, in start_session
    super(selenium.webdriver.chrome.webdriver.WebDriver, self).start_session(
  File "C:\Users\User\PycharmProjects\Socializing\venv\lib\site-packages\selenium\webdriver\remote\webdriver.py", line 378, in start_session
    response = self.execute(Command.NEW_SESSION, parameters)
  File "C:\Users\User\PycharmProjects\Socializing\venv\lib\site-packages\selenium\webdriver\remote\webdriver.py", line 440, in execute
    self.error_handler.check_response(response)
  File "C:\Users\User\PycharmProjects\Socializing\venv\lib\site-packages\selenium\webdriver\remote\errorhandler.py", line 245, in check_response
    raise exception_class(message, screen, stacktrace)
selenium.common.exceptions.WebDriverException: Message: unknown error: cannot connect to chrome at 127.0.0.1:11649
from chrome not reachable
Stacktrace:
Backtrace:
	GetHandleVerifier [0x00688893+48451]
	(No symbol) [0x0061B8A1]
	(No symbol) [0x00524F20]
	(No symbol) [0x0051B0E5]
	(No symbol) [0x00545858]
	(No symbol) [0x00540151]
	(No symbol) [0x0053FF31]
	(No symbol) [0x00570798]
	(No symbol) [0x0057047C]
	(No symbol) [0x0056A0B6]
	(No symbol) [0x00547E08]
	(No symbol) [0x00548F2D]
	GetHandleVerifier [0x008E8E3A+2540266]
	GetHandleVerifier [0x00928959+2801161]
	GetHandleVerifier [0x0092295C+2776588]
	GetHandleVerifier [0x00712280+612144]
	(No symbol) [0x00624F6C]
	(No symbol) [0x006211D8]
	(No symbol) [0x006212BB]
	(No symbol) [0x00614857]
	BaseThreadInitThunk [0x754E00C9+25]
	RtlGetAppContainerNamedObjectPath [0x771E7B4E+286]
	RtlGetAppContainerNamedObjectPath [0x771E7B1E+238]

2023-05-14 22:16:02 - Browser 1 - INFO - 初始化裝置成功 - run_script - "C:\Users\User\PycharmProjects\Socializing\core\webdriver.py:100"
2023-05-14 22:16:02 - Browser 1 - ERROR - 'NoneType' object has no attribute 'get' - run_script - "C:\Users\User\PycharmProjects\Socializing\core\webdriver.py:124"
Traceback (most recent call last):
  File "C:\Users\User\PycharmProjects\Socializing\core\webdriver.py", line 122, in run_script
    exec(script)
  File "<string>", line 15, in <module>
AttributeError: 'NoneType' object has no attribute 'get'

2023-05-14 22:16:55 - Browser 1 - INFO - 初始化裝置 - create_webdriver - "C:\Users\User\PycharmProjects\Socializing\core\webdriver.py:42"

2023-05-14 22:18:11 - Browser 1 - INFO - 初始化裝置 - create_webdriver - "C:\Users\User\PycharmProjects\Socializing\core\webdriver.py:42"

2023-05-14 22:18:24 - Browser 1 - INFO - 初始化裝置 - create_webdriver - "C:\Users\User\PycharmProjects\Socializing\core\webdriver.py:42"

2023-05-14 22:20:55 - Browser 1 - ERROR - Message: unknown error: cannot connect to chrome at 127.0.0.1:11839
from chrome not reachable
Stacktrace:
Backtrace:
	GetHandleVerifier [0x00DA6E73+48323]
	(No symbol) [0x00D39661]
	(No symbol) [0x00C451D0]
	(No symbol) [0x00C3B305]
	(No symbol) [0x00C65E08]
	(No symbol) [0x00C60854]
	(No symbol) [0x00C60631]
	(No symbol) [0x00C90DF5]
	(No symbol) [0x00C90ADC]
	(No symbol) [0x00C8A6D6]
	(No symbol) [0x00C6847C]
	(No symbol) [0x00C6957D]
	GetHandleVerifier [0x0100FD5D+2575277]
	GetHandleVerifier [0x0104F86E+2836158]
	GetHandleVerifier [0x010496DC+2811180]
	GetHandleVerifier [0x00E341B0+626688]
	(No symbol) [0x00D4314C]
	(No symbol) [0x00D3F4B8]
	(No symbol) [0x00D3F59B]
	(No symbol) [0x00D321B7]
	BaseThreadInitThunk [0x754E00C9+25]
	RtlGetAppContainerNamedObjectPath [0x771E7B4E+286]
	RtlGetAppContainerNamedObjectPath [0x771E7B1E+238]
 - create_webdriver - "C:\Users\User\PycharmProjects\Socializing\core\webdriver.py:53"
Traceback (most recent call last):
  File "C:\Users\User\PycharmProjects\Socializing\core\webdriver.py", line 51, in create_webdriver
    return uc.Chrome(**kwargs)
  File "C:\Users\User\PycharmProjects\Socializing\venv\lib\site-packages\undetected_chromedriver\__init__.py", line 441, in __init__
    super(Chrome, self).__init__(
  File "C:\Users\User\PycharmProjects\Socializing\venv\lib\site-packages\selenium\webdriver\chrome\webdriver.py", line 84, in __init__
    super().__init__(
  File "C:\Users\User\PycharmProjects\Socializing\venv\lib\site-packages\selenium\webdriver\chromium\webdriver.py", line 104, in __init__
    super().__init__(
  File "C:\Users\User\PycharmProjects\Socializing\venv\lib\site-packages\selenium\webdriver\remote\webdriver.py", line 286, in __init__
    self.start_session(capabilities, browser_profile)
  File "C:\Users\User\PycharmProjects\Socializing\venv\lib\site-packages\undetected_chromedriver\__init__.py", line 704, in start_session
    super(selenium.webdriver.chrome.webdriver.WebDriver, self).start_session(
  File "C:\Users\User\PycharmProjects\Socializing\venv\lib\site-packages\selenium\webdriver\remote\webdriver.py", line 378, in start_session
    response = self.execute(Command.NEW_SESSION, parameters)
  File "C:\Users\User\PycharmProjects\Socializing\venv\lib\site-packages\selenium\webdriver\remote\webdriver.py", line 440, in execute
    self.error_handler.check_response(response)
  File "C:\Users\User\PycharmProjects\Socializing\venv\lib\site-packages\selenium\webdriver\remote\errorhandler.py", line 245, in check_response
    raise exception_class(message, screen, stacktrace)
selenium.common.exceptions.WebDriverException: Message: unknown error: cannot connect to chrome at 127.0.0.1:11839
from chrome not reachable
Stacktrace:
Backtrace:
	GetHandleVerifier [0x00DA6E73+48323]
	(No symbol) [0x00D39661]
	(No symbol) [0x00C451D0]
	(No symbol) [0x00C3B305]
	(No symbol) [0x00C65E08]
	(No symbol) [0x00C60854]
	(No symbol) [0x00C60631]
	(No symbol) [0x00C90DF5]
	(No symbol) [0x00C90ADC]
	(No symbol) [0x00C8A6D6]
	(No symbol) [0x00C6847C]
	(No symbol) [0x00C6957D]
	GetHandleVerifier [0x0100FD5D+2575277]
	GetHandleVerifier [0x0104F86E+2836158]
	GetHandleVerifier [0x010496DC+2811180]
	GetHandleVerifier [0x00E341B0+626688]
	(No symbol) [0x00D4314C]
	(No symbol) [0x00D3F4B8]
	(No symbol) [0x00D3F59B]
	(No symbol) [0x00D321B7]
	BaseThreadInitThunk [0x754E00C9+25]
	RtlGetAppContainerNamedObjectPath [0x771E7B4E+286]
	RtlGetAppContainerNamedObjectPath [0x771E7B1E+238]

2023-05-14 22:20:55 - Browser 1 - INFO - 初始化裝置成功 - run_script - "C:\Users\User\PycharmProjects\Socializing\core\webdriver.py:102"
2023-05-14 22:20:55 - Browser 1 - ERROR - 'NoneType' object has no attribute 'get' - run_script - "C:\Users\User\PycharmProjects\Socializing\core\webdriver.py:126"
Traceback (most recent call last):
  File "C:\Users\User\PycharmProjects\Socializing\core\webdriver.py", line 124, in run_script
    exec(script)
  File "<string>", line 15, in <module>
AttributeError: 'NoneType' object has no attribute 'get'

2023-05-14 22:22:16 - Browser 1 - INFO - 初始化裝置 - create_webdriver - "C:\Users\User\PycharmProjects\Socializing\core\webdriver.py:42"

2023-05-14 22:23:26 - Browser 1 - INFO - 初始化裝置 - create_webdriver - "C:\Users\User\PycharmProjects\Socializing\core\webdriver.py:42"

2023-05-14 22:23:47 - Browser 1 - INFO - 初始化裝置 - create_webdriver - "C:\Users\User\PycharmProjects\Socializing\core\webdriver.py:42"

2023-05-14 22:24:12 - Browser 1 - INFO - 初始化裝置 - create_webdriver - "C:\Users\User\PycharmProjects\Socializing\core\webdriver.py:42"

2023-05-14 22:24:14 - Browser 1 - INFO - 初始化裝置成功 - run_script - "C:\Users\User\PycharmProjects\Socializing\core\webdriver.py:101"

2023-05-14 22:24:48 - Browser 1 - INFO - 初始化裝置 - create_webdriver - "C:\Users\User\PycharmProjects\Socializing\core\webdriver.py:42"

2023-05-14 22:25:18 - Browser 1 - INFO - 初始化裝置 - create_webdriver - "C:\Users\User\PycharmProjects\Socializing\core\webdriver.py:42"

2023-05-14 22:25:39 - Browser 1 - INFO - 初始化裝置 - create_webdriver - "C:\Users\User\PycharmProjects\Socializing\core\webdriver.py:42"

2023-05-14 22:25:40 - Browser 1 - INFO - 初始化裝置成功 - run_script - "C:\Users\User\PycharmProjects\Socializing\core\webdriver.py:101"

2023-05-14 22:25:51 - Browser 1 - ERROR - Message: 
Stacktrace:
Backtrace:
	GetHandleVerifier [0x00898893+48451]
	(No symbol) [0x0082B8A1]
	(No symbol) [0x00735058]
	(No symbol) [0x00760467]
	(No symbol) [0x0076069B]
	(No symbol) [0x0078DD92]
	(No symbol) [0x0077A304]
	(No symbol) [0x0078C482]
	(No symbol) [0x0077A0B6]
	(No symbol) [0x00757E08]
	(No symbol) [0x00758F2D]
	GetHandleVerifier [0x00AF8E3A+2540266]
	GetHandleVerifier [0x00B38959+2801161]
	GetHandleVerifier [0x00B3295C+2776588]
	GetHandleVerifier [0x00922280+612144]
	(No symbol) [0x00834F6C]
	(No symbol) [0x008311D8]
	(No symbol) [0x008312BB]
	(No symbol) [0x00824857]
	BaseThreadInitThunk [0x754E00C9+25]
	RtlGetAppContainerNamedObjectPath [0x771E7B4E+286]
	RtlGetAppContainerNamedObjectPath [0x771E7B1E+238]
 - run_script - "C:\Users\User\PycharmProjects\Socializing\core\webdriver.py:125"
Traceback (most recent call last):
  File "C:\Users\User\PycharmProjects\Socializing\core\webdriver.py", line 123, in run_script
    exec(script)
  File "<string>", line 18, in <module>
  File "C:\Users\User\PycharmProjects\Socializing\venv\lib\site-packages\selenium\webdriver\support\wait.py", line 95, in until
    raise TimeoutException(message, screen, stacktrace)
selenium.common.exceptions.TimeoutException: Message: 
Stacktrace:
Backtrace:
	GetHandleVerifier [0x00898893+48451]
	(No symbol) [0x0082B8A1]
	(No symbol) [0x00735058]
	(No symbol) [0x00760467]
	(No symbol) [0x0076069B]
	(No symbol) [0x0078DD92]
	(No symbol) [0x0077A304]
	(No symbol) [0x0078C482]
	(No symbol) [0x0077A0B6]
	(No symbol) [0x00757E08]
	(No symbol) [0x00758F2D]
	GetHandleVerifier [0x00AF8E3A+2540266]
	GetHandleVerifier [0x00B38959+2801161]
	GetHandleVerifier [0x00B3295C+2776588]
	GetHandleVerifier [0x00922280+612144]
	(No symbol) [0x00834F6C]
	(No symbol) [0x008311D8]
	(No symbol) [0x008312BB]
	(No symbol) [0x00824857]
	BaseThreadInitThunk [0x754E00C9+25]
	RtlGetAppContainerNamedObjectPath [0x771E7B4E+286]
	RtlGetAppContainerNamedObjectPath [0x771E7B1E+238]


2023-05-14 22:26:46 - Browser 1 - INFO - 初始化裝置 - create_webdriver - "C:\Users\User\PycharmProjects\Socializing\core\webdriver.py:42"

2023-05-14 22:27:09 - Browser 1 - INFO - 初始化裝置 - create_webdriver - "C:\Users\User\PycharmProjects\Socializing\core\webdriver.py:42"

2023-05-14 22:28:29 - Browser 1 - ERROR - Message: unknown error: cannot connect to chrome at 127.0.0.1:12359
from chrome not reachable
Stacktrace:
Backtrace:
	GetHandleVerifier [0x00898893+48451]
	(No symbol) [0x0082B8A1]
	(No symbol) [0x00734F20]
	(No symbol) [0x0072B0E5]
	(No symbol) [0x00755858]
	(No symbol) [0x00750151]
	(No symbol) [0x0074FF31]
	(No symbol) [0x00780798]
	(No symbol) [0x0078047C]
	(No symbol) [0x0077A0B6]
	(No symbol) [0x00757E08]
	(No symbol) [0x00758F2D]
	GetHandleVerifier [0x00AF8E3A+2540266]
	GetHandleVerifier [0x00B38959+2801161]
	GetHandleVerifier [0x00B3295C+2776588]
	GetHandleVerifier [0x00922280+612144]
	(No symbol) [0x00834F6C]
	(No symbol) [0x008311D8]
	(No symbol) [0x008312BB]
	(No symbol) [0x00824857]
	BaseThreadInitThunk [0x754E00C9+25]
	RtlGetAppContainerNamedObjectPath [0x771E7B4E+286]
	RtlGetAppContainerNamedObjectPath [0x771E7B1E+238]
 - create_webdriver - "C:\Users\User\PycharmProjects\Socializing\core\webdriver.py:53"
Traceback (most recent call last):
  File "C:\Users\User\PycharmProjects\Socializing\core\webdriver.py", line 50, in create_webdriver
    driver = uc.Chrome(user_data_dir=kwargs['user_data_dir'])
  File "C:\Users\User\PycharmProjects\Socializing\venv\lib\site-packages\undetected_chromedriver\__init__.py", line 453, in __init__
    super(Chrome, self).__init__(
  File "C:\Users\User\PycharmProjects\Socializing\venv\lib\site-packages\selenium\webdriver\chrome\webdriver.py", line 84, in __init__
    super().__init__(
  File "C:\Users\User\PycharmProjects\Socializing\venv\lib\site-packages\selenium\webdriver\chromium\webdriver.py", line 104, in __init__
    super().__init__(
  File "C:\Users\User\PycharmProjects\Socializing\venv\lib\site-packages\selenium\webdriver\remote\webdriver.py", line 286, in __init__
    self.start_session(capabilities, browser_profile)
  File "C:\Users\User\PycharmProjects\Socializing\venv\lib\site-packages\undetected_chromedriver\__init__.py", line 716, in start_session
    super(selenium.webdriver.chrome.webdriver.WebDriver, self).start_session(
  File "C:\Users\User\PycharmProjects\Socializing\venv\lib\site-packages\selenium\webdriver\remote\webdriver.py", line 378, in start_session
    response = self.execute(Command.NEW_SESSION, parameters)
  File "C:\Users\User\PycharmProjects\Socializing\venv\lib\site-packages\selenium\webdriver\remote\webdriver.py", line 440, in execute
    self.error_handler.check_response(response)
  File "C:\Users\User\PycharmProjects\Socializing\venv\lib\site-packages\selenium\webdriver\remote\errorhandler.py", line 245, in check_response
    raise exception_class(message, screen, stacktrace)
selenium.common.exceptions.WebDriverException: Message: unknown error: cannot connect to chrome at 127.0.0.1:12359
from chrome not reachable
Stacktrace:
Backtrace:
	GetHandleVerifier [0x00898893+48451]
	(No symbol) [0x0082B8A1]
	(No symbol) [0x00734F20]
	(No symbol) [0x0072B0E5]
	(No symbol) [0x00755858]
	(No symbol) [0x00750151]
	(No symbol) [0x0074FF31]
	(No symbol) [0x00780798]
	(No symbol) [0x0078047C]
	(No symbol) [0x0077A0B6]
	(No symbol) [0x00757E08]
	(No symbol) [0x00758F2D]
	GetHandleVerifier [0x00AF8E3A+2540266]
	GetHandleVerifier [0x00B38959+2801161]
	GetHandleVerifier [0x00B3295C+2776588]
	GetHandleVerifier [0x00922280+612144]
	(No symbol) [0x00834F6C]
	(No symbol) [0x008311D8]
	(No symbol) [0x008312BB]
	(No symbol) [0x00824857]
	BaseThreadInitThunk [0x754E00C9+25]
	RtlGetAppContainerNamedObjectPath [0x771E7B4E+286]
	RtlGetAppContainerNamedObjectPath [0x771E7B1E+238]

2023-05-14 22:28:30 - Browser 1 - INFO - 初始化裝置成功 - run_script - "C:\Users\User\PycharmProjects\Socializing\core\webdriver.py:102"
2023-05-14 22:28:30 - Browser 1 - ERROR - 'NoneType' object has no attribute 'get' - run_script - "C:\Users\User\PycharmProjects\Socializing\core\webdriver.py:126"
Traceback (most recent call last):
  File "C:\Users\User\PycharmProjects\Socializing\core\webdriver.py", line 124, in run_script
    exec(script)
  File "<string>", line 15, in <module>
AttributeError: 'NoneType' object has no attribute 'get'

2023-05-14 22:33:19 - Browser 1 - INFO - 初始化裝置 - create_webdriver - "C:\Users\User\PycharmProjects\Socializing\core\webdriver.py:42"

2023-05-14 22:34:45 - Browser 1 - INFO - 初始化裝置 - create_webdriver - "C:\Users\User\PycharmProjects\Socializing\core\webdriver.py:42"

